Workbook

Sheet Assumptions
B1: nVent Electric
B2: Inputs and Assumptions
S3: Notes:
F4: 2021 | G4: 2022 | H4: 2023 | I4: 2024 | J4: 2025 | K4: 2026 | L4: 2027 | M4: 2028 | N4: 2029 | S4: 1) | T4: Enclosures sales growth is divided into 4 categories in the 2024 10-K: These are: 1) Volume 2) Price 3) Acquisition 4) Currency
U5: 2021 | V5: 2022 | W5: 2023 | X5: 2024 | Y5: 2025 | Z5: 2026 | AA5: 2027 | AB5: 2028 | AC5: 2029
B6: Enclosures % growth | F6: =U10 -> 0.306 | G6: =V10 -> 0.208 | H6: =W10 -> 0.068 | I6: =X10 -> 0.135 | J6: =Y10 -> 0.27027 | K6: =Z10 -> 0.11735 | L6: =AA10 -> 0.10727 | M6: =AB10 -> 0.08715 | N6: =AC10 -> 0.07697 | T6: Volume | U6: 0.162 | V6: 0.078 | W6: 0.006 | X6: 0.054 | Y6: 0.074 | Z6: 0.084 | AA6: 0.075 | AB6: 0.055 | AC6: 0.045
B7: Electrical and Fastening Solutions % growth | F7: =U31 -> 0.155 | G7: =V31 -> 0.204 | H7: =W31 -> 0.343 | I7: =X31 -> 0.113 | J7: =Y31 -> 0.30127 | K7: =Z31 -> 0.11435 | L7: =AA31 -> 0.11027 | M7: =AB31 -> 0.10415 | N7: =AC31 -> 0.09297 | T7: Price | U7: 0.07 | V7: 0.128 | W7: 0.053 | X7: -0.004 | Y7: =0.7*0.022+0.3*0.0429 -> 0.02827 | Z7: =0.7*0.022+0.3*0.0365 -> 0.02635 | AA7: =0.7*0.022+0.3*0.0329 -> 0.02527 | AB7: =0.7*0.022+0.3*0.0325 -> 0.02515 | AC7: =0.7*0.022+0.3*0.0319 -> 0.02497 | AE7: (weighted inflation)
B8: COGS % of revenue | F8: ='Financial Forecast + DCF'!G17 -> 0.61689387 | G8: ='Financial Forecast + DCF'!H17 -> 0.64145353 | H8: ='Financial Forecast + DCF'!I17 -> 0.5971374 | I8: ='Financial Forecast + DCF'!J17 -> 0.5977845 | J8: 0.607 | K8: 0.6 | L8: 0.594 | M8: 0.587 | N8: 0.58 | T8: Acquisition | U8: 0.057 | V8: 0.038 | W8: 0.008 | X8: 0.086 | Y8: 0.168 | Z8: 0.007 | AA8: =Z8 -> 0.007 | AB8: =AA8 -> 0.007 | AC8: =AB8 -> 0.007 | AE8: (off EPG acquisition) | AG8: use 2021-2024 cagr, factor out effect of epg and evenly spread out remaining growth
B9: SG&A % of revenue | F9: ='Financial Forecast + DCF'!G23 -> 0 | G9: ='Financial Forecast + DCF'!H23 -> 0.16639798 | H9: ='Financial Forecast + DCF'!I23 -> 0.16639814 | I9: ='Financial Forecast + DCF'!J23 -> 0.15631549 | J9: =I9 -> 0.15631549 | K9: 0.153 | L9: 0.151 | M9: 0.15 | N9: 0.149 | T9: Currency | U9: 0.017 | V9: -0.036 | W9: 0.001 | X9: -0.001 | Y9: 0 | Z9: 0 | AA9: 0 | AB9: 0 | AC9: 0
B10: R&D % of revenue | F10: ='Financial Forecast + DCF'!G26 -> 0 | G10: ='Financial Forecast + DCF'!H26 -> 0.019868415 | H10: ='Financial Forecast + DCF'!I26 -> 0.020682678 | I10: ='Financial Forecast + DCF'!J26 -> 0.021988623 | J10: =I10 -> 0.021988623 | K10: =J10 -> 0.021988623 | L10: =K10 -> 0.021988623 | M10: =L10 -> 0.021988623 | N10: =M10 -> 0.021988623 | T10: Total Growth | U10: =SUM(U6:U9) -> 0.306 | V10: =SUM(V6:V9) -> 0.208 | W10: =SUM(W6:W9) -> 0.068 | X10: =SUM(X6:X9) -> 0.135 | Y10: =SUM(Y6:Y9) -> 0.27027 | Z10: =SUM(Z6:Z9) -> 0.11735 | AA10: =SUM(AA6:AA9) -> 0.10727 | AB10: =SUM(AB6:AB9) -> 0.08715 | AC10: =SUM(AC6:AC9) -> 0.07697 | AE10: (highlighted number based on management guidance)
B11: CapEx % revenue | F11: =39.5/'Financial Forecast + DCF'!G13 -> 0.020764338 | G11: =40.5/'Financial Forecast + DCF'!H13 -> 0.01764629 | H11: =65.6/'Financial Forecast + DCF'!I13 -> 0.024579415 | I11: =74/'Financial Forecast + DCF'!J13 -> 0.024616613 | J11: =AVERAGE(F11:I11) -> 0.021901664 | K11: =J11 -> 0.021901664 | L11: =K11 -> 0.021901664 | M11: =L11 -> 0.021901664 | N11: =M11 -> 0.021901664 | T11: One simple assumption is that currency fluctuations eventually average out to 0 in the long run so this entry will be 0 for the next 5 years
B12: effective tax rate | F12: 0.149 | G12: 0.128 | H12: -0.225 | I12: 0.439 | J12: 0.209 | K12: 0.209 | L12: 0.209 | M12: 0.209 | N12: 0.209 | T12: GS estimates a 2.4% cagr through 2030 in US electrical demand, with about 40% of that being tied to data centers
B13: corporate tax rate | F13: 0.25 | G13: 0.25 | H13: 0.25 | I13: 0.25 | J13: 0.25 | K13: 0.25 | L13: 0.25 | M13: 0.25 | N13: 0.25 | T13: International Energy Agency forecasts a 3.5% cagr through 2030 in global electrical demand
T14: US consists of about 70% of sales with that percentage having remained roughly the same in the past 3 years.
T15: Past 4 years have seen a CAGR of organic sales of 13.4%, with it dropping slowing down significantly in the past 2 years. (Since 2022, CAGR is 10.1%)
T16: In that same time period, electronic enclosure market had a 5.9% CAGR in the US and a 12.3% CAGR in the rest of the world (CAGR if weighted similar to nvent's sales demographic would be 7.82%)
T17: Forecasted CAGR of 6.86% and 7.7% through 2030 for US and globally, respectively. Factoring out the US given current values gives a 8% CAGR for the rest of the world giving a baseline 7.2% cagr if weighted similar to sales demographics
T18: Since 2021, nVent's enclosure business CAGR premium relative to worldwide CARG has been decreasing, however has still remained positive until these past couple of years.Given this trend, Id assume nVent's enclose business CAGR premium to become a non-factor in the coming years.
T19: Adidtionally, decrease in organic growth was due to a significant decrease in industrial and residential/commercial sales growth, likely due to raising rates. If rates were to continue at the current rate or even drop a little,
T20: reinvestment from those industries (paired with growing backlog) might help reboost the CAGR given larger revenue growth in the following years, likely driving the CAGR up by about 3-4%. Giving roughly a 13 % CAGR.
T21: Growth likely speeds up in 2025 (seeing this) and 2026 if this is true, and then slows down starting 2027 as these effects cool off and the growth slows down as the company matures
T22: PCE of 2.2% through 2029 based off fed predictions and yearly global inflation percentagles off statista
S25: 2) | T25: Electrical and Fastening Solutions sales growth is divided into 4 categories in the 2024 10-K: These are: 1) Volume 2) Price 3) Acquisition 4) Currency
U26: 2021 | V26: 2022 | W26: 2023 | X26: 2024 | Y26: 2025 | Z26: 2026 | AA26: 2027 | AB26: 2028 | AC26: 2029
T27: Volume | U27: 0.031 | V27: 0.027 | W27: -0.023 | X27: -0.017 | Y27: 0.004 | Z27: 0.05 | AA27: 0.047 | AB27: 0.041 | AC27: 0.03
T28: Price | U28: 0.106 | V28: 0.208 | W28: 0.059 | X28: 0.002 | Y28: =0.7*0.022+0.3*0.0429 -> 0.02827 | Z28: =0.7*0.022+0.3*0.0365 -> 0.02635 | AA28: =0.7*0.022+0.3*0.0329 -> 0.02527 | AB28: =0.7*0.022+0.3*0.0325 -> 0.02515 | AC28: =0.7*0.022+0.3*0.0319 -> 0.02497
T29: Acquisition | U29: 0.003 | V29: 0 | W29: 0.304 | X29: 0.128 | Y29: 0.269 | Z29: 0.038 | AA29: 0.038 | AB29: 0.038 | AC29: 0.038 | AE29: (off EPG acquisition) | AG29: use 2021-2024 cagr, factor out effect of epg and evenly spread out remaining growth
T30: Currency | U30: 0.015 | V30: -0.031 | W30: 0.003 | X30: 0 | Y30: 0 | Z30: 0 | AA30: 0 | AB30: 0 | AC30: 0
T31: Total Growth | U31: =SUM(U27:U30) -> 0.155 | V31: =SUM(V27:V30) -> 0.204 | W31: =SUM(W27:W30) -> 0.343 | X31: =SUM(X27:X30) -> 0.113 | Y31: =SUM(Y27:Y30) -> 0.30127 | Z31: =SUM(Z27:Z30) -> 0.11435 | AA31: =SUM(AA27:AA30) -> 0.11027 | AB31: =SUM(AB27:AB30) -> 0.10415 | AC31: =SUM(AC27:AC30) -> 0.09297
T32: One simple assumption is that currency fluctuations eventually average out to 0 in the long run so this entry will be 0 for the next 5 years
T33: US consists of about 70% of sales with that percentage having remained roughly the same in the past 3 years.
T34: Over the past 4 years, organic sales CAGR has been of 9.4%. Taking a look at it from 2022, CAGR has been 8%, with the CAGR for the past 2 years being about 1%.
T35: Over the past 5 years, electrical equipment CAGR was about 2.8%, with CAGR also being sharply affected in 2022 and 2023. While nVent CAGR since 2021 has been much higher, it was largely due to price increases
T36: Sales volume CAGR in tha time period has been roughly flat. However, at the same time, inflation has been roughly the same as the CAGR, therefore, organic growth may be following close to CAGR.
T37: Current forecasts expect a CAGR of 5% in the US and 5.3% outside the US for electrical equiptment through 2030. If sales volume from residential/commerical and industrial sectors rebound and a slight 1-2%CAGR premium over global CAGR is assumed due to overall trend of
T38: positive yet decreasing premium over global CAGR, it is possible that organic sales CAGR is close to the 6.5% level
S40: 3) | T40: PCE of 2.2% through 2029 based off fed predictions and yearly global inflation percentagles off statista
S42: 4) | T42: COGS as a % of revenue had improved slightly since 2023 however went up by a few percent, with management saying its due to inflation/tariffs. Assume an increase for 2025 followed by slower, gradual improvement
S44: 5) | T44: SG&A as a % of revenue has improved a lot throughout the yeats, assume that it will improve slowly as the firm continues lean initiatives and less money has to go into advertising as client base/backlog grows
S46: 6) | T46: R&D as a % of revenue has also remained constant around 2.2% so assume that remains the norm
...

Sheet Peer Comparison
A1: Company | B1: Ticker | C1: Market Cap | D1: Sector | E1: LTM Sales | F1: LTM EBITDA | G1: EBITDA Margin | H1: Operating Margin | I1: Revenue Growth | J1: LTM EV | K1: FWD P/E | L1: FWD EV/EBITDA | M1: FWD P/S
A2: nVent | B2: NVT | C2: 17190 | D2: Enclosures/Electrical Equiptment | E2: 3578.6 | F2: 675.6 | G2: =F2/E2 -> 0.18878891 | H2: 0.16 | I2: 0.126 | J2: 17648.64 | K2: 26.9 | L2: 18.77 | M2: 3.9
A3: Hubbell | B3: HUBB | C3: 22260 | D3: Enclosures/Electrical Equiptment | E3: 5686.2 | F3: 1350.4 | G3: =F3/E3 -> 0.23748725 | H3: 0.203 | I3: 0.048 | J3: 24478.88 | K3: 21.36 | L3: 15.37 | M3: 3.56
A4: Legrand (ADR) | B4: LGRDY | C4: 38450 | D4: Electrical Equiptment | E4: 9391.3 | F4: 2065.8 | G4: =F4/E4 -> 0.21996955 | H4: 0.19 | I4: 0.028 | J4: 40177.82 | K4: 21.51 | L4: 15.3 | M4: 3.31
A5: Emerson Electric | B5: EMR | C5: 71290 | D5: Enclosures/Electrical Equiptment | E5: 18061 | F5: 5040 | G5: =F5/E5 -> 0.27905432 | H5: 0.201 | I5: 0.03 | J5: 86494.1 | K5: 19.6 | L5: 15.29 | M5: 3.76
A6: Atkore Inc | B6: ATKR | C6: 2240 | D6: Enclosures/Electrical Equiptment | E6: 2886.66 | F6: 429.53 | G6: =F6/E6 -> 0.14879827 | H6: 0.083 | I6: -0.111 | J6: 3004.81 | K6: 12.41 | L6: 8.2 | M6: 0.78
A7: ABB | B7: ABBNY | C7: 125260 | D7: Enclosures/Electrical Equiptment | E7: 34508 | F7: 6942 | G7: =F7/E7 -> 0.20117074 | H7: 0.179 | I7: 0.019 | J7: 136373.92 | K7: 25.68 | L7: 16.39 | M7: 3.39
A8: Eaton | B8: ETN | C8: 132640 | D8: Enclosures/Electrical Equiptment | E8: 26633 | F8: 6146 | G8: =F8/E8 -> 0.23076634 | H8: 0.193 | I8: 0.073 | J8: 156786.53 | K8: 25.24 | L8: 19.91 | M8: 4.43
A9: Vertiv | B9: VRT | C9: 64700 | D9: Data Center Infrastructure | E9: 9696.3 | F9: 2042.1 | G9: =F9/E9 -> 0.21060611 | H9: 0.181 | I9: 0.167 | J9: 59021.9 | K9: 33.46 | L9: 24.29 | M9: 5.4
A10: Acuity | B10: AYI | C10: 10650 | D10: Electrical Equiptment | E10: 4345.6 | F10: 715.6 | G10: =F10/E10 -> 0.16467231 | H10: 0.134 | I10: 0.131 | J10: 10620.48 | K10: 17.39 | L10: 12.69 | M10: 2.2
A11: Ametek | B11: AME | C11: 43920 | D11: Electrical Equiptment | E11: 7164.27 | F11: 2267.58 | G11: =F11/E11 -> 0.31651236 | H11: 0.259 | I11: 0.052 | J11: 44998.33 | K11: 24.33 | L11: 18.54 | M11: 5.61
J12: Mean | K12: =AVERAGE(K3,K4,K5,K7,K8,K10,K11) -> 22.158571 | L12: =AVERAGE(L3,L4,L5,L7,L8,L10,L11) -> 16.212857 | M12: =AVERAGE(M3,M4,M5,M7,M8,M10,M11,M9) -> 3.9575
J13: Median | K13: =MEDIAN(K3:K11) -> 21.51 | L13: =MEDIAN(L3:L11) -> 15.37 | M13: =MEDIAN(M3:M11) -> 3.56
J14: Q1 | K14: =_xlfn.QUARTILE.EXC(K3:K11,1) -> 18.495 | L14: =_xlfn.QUARTILE.EXC(L3:L11,1) -> 13.99 | M14: =_xlfn.QUARTILE.EXC(M3:M11,1) -> 2.755
J15: Q3 | K15: =_xlfn.QUARTILE.EXC(K3:K11,3) -> 25.46 | L15: =_xlfn.QUARTILE.EXC(L3:L11,3) -> 19.225 | M15: =_xlfn.QUARTILE.EXC(M3:M11,3) -> 4.915
J16: IQR | K16: =K15-K14 -> 6.965 | L16: =L15-L14 -> 5.235 | M16: =M15-M14 -> 2.16
J17: Outlier Boundary | K17: (14.55, 28.48) | L17: (10.14, 20.61) | M17: (1.4, 5.72)
K18: =K13+K16 -> 28.475 | L18: =L13+L16 -> 20.605 | M18: =M13+M16 -> 5.72
K19: =K13-K16 -> 14.545 | L19: =L13-L16 -> 10.135 | M19: =M13-M16 -> 1.4
G21: NVT Comparable Company PPS Valuation
I22: Forecasted PPS | J22: FWD EV/EBITDA
G23: Mean W/O Ouliers | I23: =K12*4 -> 88.634286 | J23: n/a | K23: Forward EPS forecast is ~ $4
G24: Median | I24: =K13*4 -> 86.04 | J24: n/a | K24: Forward EBITDA forecast not available
G25: Q1 Price | I25: =K14*4 -> 73.98 | J25: n/a
G26: Q3 Price | I26: =K15*4 -> 101.84 | J26: n/a

Sheet Scenarios
B1: Company Name
B2: nVent Electric
K5: Projected
B6: Scenario Switch | D6: 2 | G6: =[1]Assumptions!H6 -> 2025 | H6: =G6+1 -> 2026 | I6: =H6+1 -> 2027 | J6: =I6+1 -> 2028 | K6: =J6+1 -> 2029
B9: Revenue Drivers
C11: Driver one | G11: =CHOOSE($D$6, G12,G13,G14) -> 0.27027 | H11: =CHOOSE($D$6, H12,H13,H14) -> 0.11735 | I11: =CHOOSE($D$6, I12,I13,I14) -> 0.10727 | J11: =CHOOSE($D$6, J12,J13,J14) -> 0.08715 | K11: =CHOOSE($D$6, K12,K13,K14) -> 0.07697
D12: Best Case | G12: =G13*1.1 -> 0.297297 | H12: =H13*1.1 -> 0.129085 | I12: =I13*1.1 -> 0.117997 | J12: =J13*1.1 -> 0.095865 | K12: =K13*1.1 -> 0.084667
D13: Base Case | G13: =Assumptions!J6 -> 0.27027 | H13: =Assumptions!K6 -> 0.11735 | I13: =Assumptions!L6 -> 0.10727 | J13: =Assumptions!M6 -> 0.08715 | K13: =Assumptions!N6 -> 0.07697
D14: Worst Case | G14: =G13*0.9 -> 0.243243 | H14: =H13*0.9 -> 0.105615 | I14: =I13*0.9 -> 0.096543 | J14: =J13*0.9 -> 0.078435 | K14: =K13*0.9 -> 0.069273
C16: Driver two | G16: =CHOOSE($D$6, G17,G18,G19) -> 0.30127 | H16: =CHOOSE($D$6, H17,H18,H19) -> 0.11435 | I16: =CHOOSE($D$6, I17,I18,I19) -> 0.11027 | J16: =CHOOSE($D$6, J17,J18,J19) -> 0.10415 | K16: =CHOOSE($D$6, K17,K18,K19) -> 0.09297
D17: Best Case | G17: =G18*1.1 -> 0.331397 | H17: =H18*1.1 -> 0.125785 | I17: =I18*1.1 -> 0.121297 | J17: =J18*1.1 -> 0.114565 | K17: =K18*1.1 -> 0.102267
D18: Base Case | G18: =Assumptions!J7 -> 0.30127 | H18: =Assumptions!K7 -> 0.11435 | I18: =Assumptions!L7 -> 0.11027 | J18: =Assumptions!M7 -> 0.10415 | K18: =Assumptions!N7 -> 0.09297
D19: Worst Case | G19: =G18*0.9 -> 0.271143 | H19: =H18*0.9 -> 0.102915 | I19: =I18*0.9 -> 0.099243 | J19: =J18*0.9 -> 0.093735 | K19: =K18*0.9 -> 0.083673
B21: COGS
C23: % revenue | G23: =CHOOSE($D$6,G24, G25,G26) -> 0.607 | H23: =CHOOSE($D$6,H24, H25,H26) -> 0.6 | I23: =CHOOSE($D$6,I24, I25,I26) -> 0.594 | J23: =CHOOSE($D$6,J24, J25,J26) -> 0.587 | K23: =CHOOSE($D$6,K24, K25,K26) -> 0.58
D24: Best Case | G24: =G25*0.9 -> 0.5463 | H24: =H25*0.9 -> 0.54 | I24: =I25*0.9 -> 0.5346 | J24: =J25*0.9 -> 0.5283 | K24: =K25*0.9 -> 0.522
D25: Base Case | G25: =Assumptions!J8 -> 0.607 | H25: =Assumptions!K8 -> 0.6 | I25: =Assumptions!L8 -> 0.594 | J25: =Assumptions!M8 -> 0.587 | K25: =Assumptions!N8 -> 0.58
D26: Worst Case | G26: =G25*1.1 -> 0.6677 | H26: =H25*1.1 -> 0.66 | I26: =I25*1.1 -> 0.6534 | J26: =J25*1.1 -> 0.6457 | K26: =K25*1.1 -> 0.638

Sheet D&A Calculations
O1: =UPPER("currently running: " &CHOOSE(Scenarios!$D$6, Scenarios!$D$12,Scenarios!$D$13, Scenarios!$D$14)&" scenario") -> CURRENTLY RUNNING: BASE CASE SCENARIO
B2: nVent Electric
B3: Depreciation Schedule
K5: projected
G6: 2021 | H6: =I6-1 -> 2022 | I6: =J6-1 -> 2023 | J6: =K6-1 -> 2024 | K6: =[1]Assumptions!$H$6 -> 2025 | L6: =K6+1 -> 2026 | M6: =L6+1 -> 2027 | N6: =M6+1 -> 2028 | O6: =N6+1 -> 2029
B8: Beginning Fixed Assets (PP&E) | F8: MM | K8: =J13 -> 347.9 | L8: =K13 -> 401.66667 | M8: =L13 -> 435.00872 | N8: =M13 -> 473.22294 | O8: =N13 -> 515.35224
B9: Plus: Capex | F9: MM | K9: 110 | L9: =Assumptions!K11*'Financial Forecast + DCF'!L13 -> 94.24327 | M9: =Assumptions!L11*'Financial Forecast + DCF'!M13 -> 104.46544 | N9: =Assumptions!M11*'Financial Forecast + DCF'!N13 -> 114.27862 | O9: =Assumptions!N11*'Financial Forecast + DCF'!O13 -> 123.81145 | P9: 2025 is 110 off management assumptinos
B11: Total Depreciation | F11: MM | K11: =0.14*K13 -> 56.233333 | L11: =0.14*L13 -> 60.90122 | M11: =0.14*M13 -> 66.251212 | N11: =0.14*N13 -> 72.149314 | O11: =0.14*O13 -> 78.493787 | P11: depreciation is about 14 % of total PP&E value
B13: Ending Fixed Assets (PP&E) | F13: MM | J13: 347.9 | K13: =K8 + K9-K11 -> 401.66667 | L13: =L8 + L9-L11 -> 435.00872 | M13: =M8 + M9-M11 -> 473.22294 | N13: =N8 + N9-N11 -> 515.35224 | O13: =O8 + O9-O11 -> 560.66991
B15: Expected Amortization | F15: MM | K15: 112.6 | L15: 102.1 | M15: 89.7 | N15: 89.6 | O15: 89.6 | P15: based off forecasts from 10k however 2025 amortization goes up by about
B17: Total D&A | F17: MM | K17: =SUM(K11+K15) -> 168.83333 | L17: =SUM(L11,L15) -> 163.00122 | M17: =SUM(M11,M15) -> 155.95121 | N17: =SUM(N11,N15) -> 161.74931 | O17: =SUM(O11,O15) -> 168.09379
B19: Total D& A considering Management Forecast | F19: MM | K19: 205 | L19: =(205/168.83)*L17 -> 197.92247 | M19: =(205/168.83)*M17 -> 189.36207 | N19: =(205/168.83)*N17 -> 196.40235 | O19: =(205/168.83)*O17 -> 204.10606 | P19: 2025 total is 205 off management assumptions, assume that this growth continues into future

Sheet Working Capital Schedule
B1: nVent Electric
B2: Working Capital Schedule
K5: projected
G6: 2021 | H6: =I6-1 -> 2022 | I6: =J6-1 -> 2023 | J6: =K6-1 -> 2024 | K6: =[1]Assumptions!$H$6 -> 2025 | L6: =K6+1 -> 2026 | M6: =L6+1 -> 2027 | N6: =M6+1 -> 2028 | O6: =N6+1 -> 2029
B8: Days Per Year | H8: 365 | I8: =DATE(I6, 12,31) - DATE(H6, 12, 31) -> 365 | J8: =DATE(J6, 12,31) - DATE(I6, 12, 31) -> 366 | K8: =DATE(K6, 12,31) - DATE(J6, 12, 31) -> 365 | L8: =DATE(L6, 12,31) - DATE(K6, 12, 31) -> 365 | M8: =DATE(M6, 12,31) - DATE(L6, 12, 31) -> 365 | N8: =DATE(N6, 12,31) - DATE(M6, 12, 31) -> 366 | O8: =DATE(O6, 12,31) - DATE(N6, 12, 31) -> 365
B10: Income Statement Items
C11: Revenue | F11: MM | G11: ='Financial Forecast + DCF'!G13 -> 1902.3 | H11: ='Financial Forecast + DCF'!H13 -> 2295.1 | I11: ='Financial Forecast + DCF'!I13 -> 2668.9 | J11: ='Financial Forecast + DCF'!J13 -> 3006.1 | K11: ='Financial Forecast + DCF'!K13 -> 3855.2254 | L11: ='Financial Forecast + DCF'!L13 -> 4303.0187 | M11: ='Financial Forecast + DCF'!M13 -> 4769.749 | N11: ='Financial Forecast + DCF'!N13 -> 5217.8052 | O11: ='Financial Forecast + DCF'!O13 -> 5653.0613
C12: COGS | F12: MM | G12: ='Financial Forecast + DCF'!G16 -> 1173.5172 | H12: ='Financial Forecast + DCF'!H16 -> 1472.2 | I12: ='Financial Forecast + DCF'!I16 -> 1593.7 | J12: ='Financial Forecast + DCF'!J16 -> 1797 | K12: ='Financial Forecast + DCF'!K16 -> 2340.1218 | L12: ='Financial Forecast + DCF'!L16 -> 2581.8112 | M12: ='Financial Forecast + DCF'!M16 -> 2833.2309 | N12: ='Financial Forecast + DCF'!N16 -> 3062.8517 | O12: ='Financial Forecast + DCF'!O16 -> 3278.7756
B14: Days In
C15: Accounts Receivable | F15: days | H15: =AVERAGE(H20,G20)/I11*I8 -> 62.267039 | I15: =AVERAGE(H20,I20)/I11*I8 -> 64.462044 | J15: =AVERAGE(I20,J20)/J11*J8 -> 57.424537 | K15: =AVERAGE(J20,K20)/K11*K8 -> 45.664106 | L15: =AVERAGE(K20,L20)/L11*L8 -> 42.152622 | M15: =AVERAGE(L20,M20)/M11*M8 -> 38.878042 | N15: =AVERAGE(M20,N20)/N11*N8 -> 36.439602 | O15: =AVERAGE(N20,O20)/O11*O8 -> 34.289075
C16: Inventories | F16: days | H16: =AVERAGE(G22,H22)/I12*I8 -> 76.563657 | I16: =AVERAGE(I22,H22)/I12*I8 -> 80.94952 | J16: =AVERAGE(J22,I22)/J12*J8 -> 73.373122 | K16: =AVERAGE(K22,J22)/K12*K8 -> 58.120555 | L16: =AVERAGE(L22,K22)/L12*L8 -> 55.370494 | M16: =AVERAGE(M22,L22)/M12*M8 -> 52.219006 | N16: =AVERAGE(N22,M22)/N12*N8 -> 50.091226 | O16: =AVERAGE(O22,N22)/O12*O8 -> 48.197166
C17: Accounts Payable | F17: days | H17: =AVERAGE(H24,G24)/G12*I8 -> 79.794953 | I17: =AVERAGE(H24,I24)/I12*I8 -> 56.32914 | J17: =AVERAGE(I24,J24)/J12*J8 -> 52.944741 | K17: =AVERAGE(I17,J17) -> 54.63694 | L17: =K17 -> 54.63694 | M17: =L17 -> 54.63694 | N17: =M17 -> 54.63694 | O17: =N17 -> 54.63694
B19: Account Balances
C20: Accounts Receivable | F20: MM | G20: 438.1 | H20: 472.5 | I20: 470.2 | J20: 473.1 | K20: =$J$20 + ((8/58)*(K11/$J$11-1)*J20) -> 491.53246 | L20: =$J$20 + ((8/58)*(L11/$J$11-1)*K20) -> 502.34984 | M20: =$J$20 + ((8/58)*(M11/$J$11-1)*L20) -> 513.75154 | N20: =$J$20 + ((8/58)*(N11/$J$11-1)*M20) -> 525.23615 | O20: =$J$20 + ((8/58)*(O11/$J$11-1)*N20) -> 536.8912 | Q20: DSO decreased paired with a 8% AR growth despite seeing a 58% growth in revenue makes me
C21: % of revenue | G21: =G20/G11 -> 0.23030016 | H21: =H20/H11 -> 0.20587338 | I21: =I20/I11 -> 0.17617745 | J21: =J20/J11 -> 0.15737999 | K21: =K20/K11 -> 0.12749772 | L21: =L20/L11 -> 0.11674359 | M21: =M20/M11 -> 0.10771039 | N21: =N20/N11 -> 0.10066228 | O21: =O20/O11 -> 0.094973532 | Q21: believe that this will continue to grow at a slow rate like this one we've seen
C22: Inventories | F22: MM | G22: 321.9 | H22: 346.7 | I22: 360.2 | J22: 360.3 | K22: =$J$22+((K12/$J$12-1)*(12/53)*J22) -> 384.95578 | L22: =$J$22+((L12/$J$12-1)*(12/53)*K22) -> 398.36566 | M22: =$J$22+((M12/$J$12-1)*(12/53)*L22) -> 412.31106 | N22: =$J$22+((N12/$J$12-1)*(12/53)*M22) -> 426.0605 | O22: =$J$22+((O12/$J$12-1)*(12/53)*N22) -> 439.84465 | Q22: I believe that inventory levels likely stay pretty flat, especially considering backlog growth.
C23: % of COGS | G23: =G22/G12 -> 0.27430361 | H23: =H22/H12 -> 0.23549789 | I23: =I22/I12 -> 0.22601493 | J23: =J22/J12 -> 0.20050083 | K23: =K22/K12 -> 0.16450245 | L23: =L22/L12 -> 0.15429697 | M23: =M22/M12 -> 0.14552681 | N23: =N22/N12 -> 0.13910582 | O23: =O22/O12 -> 0.13414906 | Q23: ~53% growth in cogs only saw a 12% growth in inventory levels, assume similar growth occurs
C24: Accounts Payable | F24: MM | G24: 261 | H24: 252.1 | I24: 239.8 | J24: 280.1 | K24: =$J$24+((7/53)*(K12/$J$12-1)*J24) -> 291.2811 | L24: =$J$24+((7/53)*(L12/$J$12-1)*K24) -> 296.90164 | M24: =$J$24+((7/53)*(M12/$J$12-1)*L24) -> 302.71222 | N24: =$J$24+((7/53)*(N12/$J$12-1)*M24) -> 308.26352 | O24: =$J$24+((7/53)*(O12/$J$12-1)*N24) -> 313.67211 | Q24: DPO decreased paired with a 7% AP growth despite seeing a 53% growth in COGS makes me
C25: % of COGS | G25: =G24/G12 -> 0.22240833 | H25: =H24/H12 -> 0.17124032 | I25: =I24/I12 -> 0.15046747 | J25: =J24/J12 -> 0.1558709 | K25: =K24/K12 -> 0.12447262 | L25: =L24/L12 -> 0.11499742 | M25: =M24/M12 -> 0.10684347 | N25: =N24/N12 -> 0.10064592 | O25: =O24/O12 -> 0.095667454 | Q25: believe that this will continue to grow at a slow rate like this one we've seen
O32: 5.3 | P32: = | Q32: cogs/((360.3+x)/2)

Sheet Financial Forecast + DCF
O1: =UPPER("currently running: " &CHOOSE(Scenarios!$D$6, Scenarios!$D$12,Scenarios!$D$13, Scenarios!$D$14)&" scenario") -> CURRENTLY RUNNING: BASE CASE SCENARIO
B2: nVent Electric
B3: Income Statement
K6: projected
G7: 2021 | H7: =I7-1 -> 2022 | I7: =J7-1 -> 2023 | J7: =K7-1 -> 2024 | K7: =[1]Assumptions!$H$6 -> 2025 | L7: =K7+1 -> 2026 | M7: =L7+1 -> 2027 | N7: =M7+1 -> 2028 | O7: =N7+1 -> 2029
B9: Enclosures | E9: $MM | G9: 1244.8 | H9: 1503.7 | I9: 1605.9 | J9: 1823.3 | K9: =J9*(1+K10) -> 2316.0833 | L9: =K9*(1+L10) -> 2587.8757 | M9: =L9*(1+M10) -> 2865.4771 | N9: =M9*(1+N10) -> 3115.2034 | O9: =N9*(1+O10) -> 3354.9806
C10: % growth | H10: =H9/G9 - 1 -> 0.20798522 | I10: =I9/H9 - 1 -> 0.067965685 | J10: =J9/I9 - 1 -> 0.1353758 | K10: =Scenarios!G11 -> 0.27027 | L10: =Scenarios!H11 -> 0.11735 | M10: =Scenarios!I11 -> 0.10727 | N10: =Scenarios!J11 -> 0.08715 | O10: =Scenarios!K11 -> 0.07697
B11: Electrical & Fastening Solutions | E11: $MM | G11: 657.5 | H11: 791.4 | I11: 1063 | J11: 1182.8 | K11: =J11*(1+K12) -> 1539.1422 | L11: =K11*(1+L12) -> 1715.1431 | M11: =L11*(1+M12) -> 1904.2719 | N11: =M11*(1+N12) -> 2102.6018 | O11: =N11*(1+O12) -> 2298.0807
C12: % growth | H12: =H11/G11 - 1 -> 0.20365019 | I12: =I11/H11 - 1 -> 0.34318928 | J12: =J11/I11 - 1 -> 0.11269991 | K12: =Scenarios!G16 -> 0.30127 | L12: =Scenarios!H16 -> 0.11435 | M12: =Scenarios!I16 -> 0.11027 | N12: =Scenarios!J16 -> 0.10415 | O12: =Scenarios!K16 -> 0.09297
B13: Total Revenue | E13: $MM | G13: =G9+G11 -> 1902.3 | H13: =H9+H11 -> 2295.1 | I13: =I9+I11 -> 2668.9 | J13: =J9+J11 -> 3006.1 | K13: =K9+K11 -> 3855.2254 | L13: =L9+L11 -> 4303.0187 | M13: =M9+M11 -> 4769.749 | N13: =N9+N11 -> 5217.8052 | O13: =O9+O11 -> 5653.0613
C14: % growth | H14: =H13/G13 - 1 -> 0.20648688 | I14: =I13/H13 - 1 -> 0.16286872 | J14: =J13/I13 - 1 -> 0.12634419 | K14: =K13/J13 - 1 -> 0.28246747 | L14: =L13/K13 - 1 -> 0.11615229 | M14: =M13/L13 - 1 -> 0.10846577 | N14: =N13/M13 - 1 -> 0.09393707 | O14: =O13/N13 - 1 -> 0.083417467
B16: COGS | E16: $MM | G16: =1520.1*0.772 -> 1173.5172 | H16: 1472.2 | I16: 1593.7 | J16: 1797 | K16: =K13*K17 -> 2340.1218 | L16: =L13*L17 -> 2581.8112 | M16: =M13*M17 -> 2833.2309 | N16: =N13*N17 -> 3062.8517 | O16: =O13*O17 -> 3278.7756
C17: % revenue | G17: =G16/G13 -> 0.61689387 | H17: =H16/H13 -> 0.64145353 | I17: =I16/I13 -> 0.5971374 | J17: =J16/J13 -> 0.5977845 | K17: =Scenarios!G23 -> 0.607 | L17: =Scenarios!H23 -> 0.6 | M17: =Scenarios!I23 -> 0.594 | N17: =Scenarios!J23 -> 0.587 | O17: =Scenarios!K23 -> 0.58
B19: Gross Profit | E19: $MM | G19: =G13-G16 -> 728.7828 | H19: =H13-H16 -> 822.9 | I19: =I13-I16 -> 1075.2 | J19: =J13-J16 -> 1209.1 | K19: =K13-K16 -> 1515.1036 | L19: =L13-L16 -> 1721.2075 | M19: =M13-M16 -> 1936.5181 | N19: =N13-N16 -> 2154.9536 | O19: =O13-O16 -> 2374.2858
C20: % growth | H20: =H19/G19 - 1 -> 0.129143 | I20: =I19/H19 - 1 -> 0.30659861 | J20: =J19/I19 - 1 -> 0.12453497 | K20: =K19/J19 - 1 -> 0.25308378 | L20: =L19/K19 - 1 -> 0.13603287 | M20: =M19/L19 - 1 -> 0.12509276 | N20: =N19/M19 - 1 -> 0.11279805 | O20: =O19/N19 - 1 -> 0.10178048
B22: SG&A | E22: $MM | H22: =468.3-H28 -> 381.9 | I22: =557.3-I28 -> 444.1 | J22: =615.9-J28 -> 469.9 | K22: =K13*K23 -> 602.63146 | L22: =L13*L23 -> 658.36187 | M22: =M13*M23 -> 720.2321 | N22: =N13*N23 -> 782.67078 | O22: =O13*O23 -> 842.30614
C23: % revenue | H23: =H22/H13 -> 0.16639798 | I23: =I22/I13 -> 0.16639814 | J23: =J22/J13 -> 0.15631549 | K23: =Assumptions!J9 -> 0.15631549 | L23: =Assumptions!K9 -> 0.153 | M23: =Assumptions!L9 -> 0.151 | N23: =Assumptions!M9 -> 0.15 | O23: =Assumptions!N9 -> 0.149
B25: R&D | E25: $MM | H25: 45.6 | I25: 55.2 | J25: 66.1 | K25: =K13*K26 -> 84.771099 | L25: =L13*L26 -> 94.617457 | M25: =M13*M26 -> 104.88021 | N25: =N13*N26 -> 114.73235 | O25: =O13*O26 -> 124.30303
C26: % revenue | H26: =H25/H13 -> 0.019868415 | I26: =I25/I13 -> 0.020682678 | J26: =J25/J13 -> 0.021988623 | K26: =Assumptions!J10 -> 0.021988623 | L26: =Assumptions!K10 -> 0.021988623 | M26: =Assumptions!L10 -> 0.021988623 | N26: =Assumptions!M10 -> 0.021988623 | O26: =Assumptions!N10 -> 0.021988623
B28: D&A | E28: $MM | H28: 86.4 | I28: 113.2 | J28: 146 | K28: ='D&A Calculations'!K19 -> 205 | L28: ='D&A Calculations'!L19 -> 197.92247 | M28: ='D&A Calculations'!M19 -> 189.36207 | N28: ='D&A Calculations'!N19 -> 196.40235 | O28: ='D&A Calculations'!O19 -> 204.10606
B30: Operating Income (EBIT) | E30: $MM | H30: =H19-H22-H25-H28 -> 309 | I30: =I19-I22-I25-I28 -> 462.7 | J30: =J19-J22-J25-J28 -> 527.1 | K30: =K19-K22-K25-K28 -> 622.70104 | L30: =L19-L22-L25-L28 -> 770.3057 | M30: =M19-M22-M25-M28 -> 922.0437 | N30: =N19-N22-N25-N28 -> 1061.1481 | O30: =O19-O22-O25-O28 -> 1203.5705
C31: % growth | H31: 0.239 | I31: =I30/H30 - 1 -> 0.497411 | J31: =J30/I30 - 1 -> 0.13918306 | K31: =K30/J30 - 1 -> 0.18137173 | L31: =L30/K30 - 1 -> 0.23703937 | M31: =M30/L30 - 1 -> 0.19698414 | N31: =N30/M30 - 1 -> 0.15086526 | O31: =O30/N30 - 1 -> 0.13421544
B33: Interest Expense | E33: $MM | H33: 31.2 | I33: 79.4 | J33: 106 | K33: =(271.6*0.05416)+(500*0.0455)+(300*0.0275)+(500*0.0565) -> 73.959856 | L33: =(271.6*0.05416)+(500*0.0455)+(300*0.0275)+(500*0.0565) -> 73.959856 | M33: =(271.6*0.05416)+(500*0.0455)+(300*0.0275)+(500*0.0565) -> 73.959856 | N33: =(271.6*0.05416)+(500*0.0455)+(300*0.0275)+(500*0.0565) -> 73.959856 | O33: =(271.6*0.05416)+(300*0.0275)+(500*0.0565) -> 51.209856 | Q33: Paid off debt for last acquisition within a year so I will assume that debt levels wont increase significantly
B35: Pre-Tax Income (EBT) | E35: $MM | H35: =H30-H33 -> 277.8 | I35: =I30-I33 -> 383.3 | J35: =J30-J33 -> 421.1 | K35: =K30-K33 -> 548.74118 | L35: =L30-L33 -> 696.34585 | M35: =M30-M33 -> 848.08385 | N35: =N30-N33 -> 987.18821 | O35: =O30-O33 -> 1152.3607
B37: Income Taxes | E37: $MM | H37: =H35*H38 -> 35.5584 | I37: =I35*I38 -> -86.2425 | J37: =J35*J38 -> 184.8629 | K37: =K35*K38 -> 114.68691 | L37: =L35*L38 -> 145.53628 | M37: =M35*M38 -> 177.24952 | N37: =N35*N38 -> 206.32234 | O37: =O35*O38 -> 240.84338
C38: effective tax rate | H38: =Assumptions!G12 -> 0.128 | I38: =Assumptions!H12 -> -0.225 | J38: =Assumptions!I12 -> 0.439 | K38: =Assumptions!J12 -> 0.209 | L38: =Assumptions!K12 -> 0.209 | M38: =Assumptions!L12 -> 0.209 | N38: =Assumptions!M12 -> 0.209 | O38: =Assumptions!N12 -> 0.209
B40: Net Income | E40: $MM | H40: =H35-H37 -> 242.2416 | I40: =I35-I37 -> 469.5425 | J40: =J35-J37 -> 236.2371 | K40: =K35-K37 -> 434.05428 | L40: =L35-L37 -> 550.80956 | M40: =M35-M37 -> 670.83432 | N40: =N35-N37 -> 780.86587 | O40: =O35-O37 -> 911.51729
A43: DCF
E46: 2025 | F46: 2026 | G46: 2027 | H46: 2028 | I46: 2029 | M46: WACC ↓/Terminal Growth Rate → | N46: 0.025 | O46: 0.0275 | P46: 0.03 | Q46: 0.0325 | R46: 0.035
B47: NOPAT | E47: =K30-K37 -> 508.01413 | F47: =L30-L37 -> 624.76942 | G47: =M30-M37 -> 744.79418 | H47: =N30-N37 -> 854.82573 | I47: =O30-O37 -> 962.72714 | M47: 0.0857 | N47: 81.17 | O47: 84.4 | P47: 87.92 | Q47: 91.77 | R47: 96 | T47: median | U47: =MEDIAN(N47:R51) -> 79.68
A48: + | B48: D&A | E48: =K28 -> 205 | F48: =L28 -> 197.92247 | G48: =M28 -> 189.36207 | H48: =N28 -> 196.40235 | I48: =O28 -> 204.10606 | M48: 0.0882 | N48: 77.45 | O48: 80.4 | P48: 83.6 | Q48: 87.08 | R48: 90.9 | T48: q1 | U48: =_xlfn.QUARTILE.EXC(N47:R51,1) -> 74.65 | W48: iqr | X48: =U49-U48 -> 10.705
A49: - | B49: Capex | E49: ='D&A Calculations'!K9 -> 110 | F49: ='D&A Calculations'!L9 -> 94.24327 | G49: ='D&A Calculations'!M9 -> 104.46544 | H49: ='D&A Calculations'!N9 -> 114.27862 | I49: ='D&A Calculations'!O9 -> 123.81145 | M49: 0.0907 | N49: 74.05 | O49: 76.75 | P49: 79.68 | Q49: 82.85 | R49: 86.31 | T49: q3 | U49: =_xlfn.QUARTILE.EXC(N47:R51,3) -> 85.355
A50: - | B50: Change in NWC | E50: =('Working Capital Schedule'!K20+'Working Capital Schedule'!K22-'Working Capital Schedule'!K24)-('Working Capital Schedule'!J20+'Working Capital Schedule'!J22-'Working Capital Schedule'!J24) -> 31.90715 | F50: =('Working Capital Schedule'!L20+'Working Capital Schedule'!L22-'Working Capital Schedule'!L24)-('Working Capital Schedule'!K20+'Working Capital Schedule'!K22-'Working Capital Schedule'!K24) -> 18.606716 | G50: =('Working Capital Schedule'!M20+'Working Capital Schedule'!M22-'Working Capital Schedule'!M24)-('Working Capital Schedule'!L20+'Working Capital Schedule'!L22-'Working Capital Schedule'!L24) -> 19.536516 | H50: =('Working Capital Schedule'!N20+'Working Capital Schedule'!N22-'Working Capital Schedule'!N24)-('Working Capital Schedule'!M20+'Working Capital Schedule'!M22-'Working Capital Schedule'!M24) -> 19.682752 | I50: =('Working Capital Schedule'!O20+'Working Capital Schedule'!O22-'Working Capital Schedule'!O24)-('Working Capital Schedule'!N20+'Working Capital Schedule'!N22-'Working Capital Schedule'!N24) -> 20.030611 | M50: 0.0932 | N50: 70.83 | O50: 73.3 | P50: 75.98 | Q50: 78.87 | R50: 82.01 | T50: upper bound | U50: =U49+1.5*X48 -> 101.4125
A51: = | B51: Unlevered Free Cash Flow | E51: =E47+E48-E49-E50 -> 571.10698 | F51: =F47+F48-F49-F50 -> 709.8419 | G51: =G47+G48-G49-G50 -> 810.1543 | H51: =H47+H48-H49-H50 -> 917.26672 | I51: =I47+I48-I49-I50 -> 1022.9911 | M51: 0.0957 | N51: 67.87 | O51: 70.15 | P51: 72.6 | Q51: 75.25 | R51: 78.12 | T51: lower bound | U51: =U48-1.5*X48 -> 58.5925
B53: Present Value of UFCF | E53: =E51/(1+WACC!$D$16)^(E46-2024) -> 523.62983 | F53: =F51/(1+WACC!$D$16)^(F46-2024) -> 596.72667 | G53: =G51/(1+WACC!$D$16)^(G46-2024) -> 624.43677 | H53: =H51/(1+WACC!$D$16)^(H46-2024) -> 648.22126 | I53: =I51/(1+WACC!$D$16)^(I46-2024) -> 662.83651
B54: Terminal Value | I54: =(I51*(1+WACC!D18))/(WACC!D16-WACC!D18) -> 17367.611
B55: Present Value of Terminal Value | I55: =I54/(1+WACC!D16)^5 -> 11253.164
B56: Enterprise Value | I56: =SUM(E53:I53,I55) -> 14309.015
A57: - | B57: Debt | I57: =WACC!D2 -> 1579.5
A58: + | B58: Cash | I58: 126.9
...

Sheet WACC
A1: WACC CALCULATIONS
C2: Total Debt: | D2: 1579.5
C3: Cost of Debt: | D3: =0.0106+0.0388 -> 0.0494 | F3: YTM on long term bonds, default spread on credit rating + rfr if no bonds, or calculate interest coverage ratio (EBIT/interest) and find credit default spread given this and add to rfr
C4: % Debt: | D4: =D2/D14 -> 0.084152481 | F4: used second option due to lack of clarity of option 1
C5: Tax Rate: | D5: =Assumptions!J12 -> 0.209
C7: Equity Value: | D7: 17190 | F7: 106.55 close 11/14 with shares outstanding being 161.36 million
C8: Cost of Equity: | D8: =D10+D11*D12 -> 0.09541
C9: % Equity: | D9: =D7/D14 -> 0.91584752
C10: Risk-Free Rate: | D10: 0.0388
C11: Beta: | D11: 1.258 | F11: levered beta is used in wacc calculations
C12: Market-Risk Premium: | D12: 0.045
C14: Debt + Equity: | D14: =D2+D7 -> 18769.5
C16: WACC: | D16: =(D3*D4*(1-D5))+(D9*(D10+D11*D12)) -> 0.090669304
B18: Terminal Growth Rate: | D18: 0.03 | F18: terminal growth rate must be greater than inflation rate (3%) but less than hisotrical gdp growth rate (3.3%)

Sheet Miscellaneous Charts
A1: Date | B1: S&P500 | C1: S&P500 | D1: XLI | E1: XLI | F1: NVT | G1: NVT | Q1: Systems Protection | R1: Electrical Connections
A2: 45659 | B2: 5868.55 | C2: 100 | D2: 131.3 | E2: 100 | F2: 68.46 | G2: 100 | Q2: 0.61 | R2: 0.39
A3: 45688 | B3: 6040.53 | C3: =C2*(1+(B3/B2-1)) -> 102.93054 | D3: 138.35 | E3: =E2*(1+(D3/D2-1)) -> 105.36938 | F3: 65.09 | G3: =G2*(1+(F3/F2-1)) -> 95.077417 | P3: North America | Q3: 0.73 | R3: 0.71
A4: 45716 | B4: 5954.5 | C4: =C3*(1+(B4/B3-1)) -> 101.46459 | D4: 136.33 | E4: =E3*(1+(D4/D3-1)) -> 103.83092 | F4: 60.34 | G4: =G3*(1+(F4/F3-1)) -> 88.139059 | P4: Rest of World | Q4: 0.27 | R4: 0.29
A5: 45747 | B5: 5611.85 | C5: =C4*(1+(B5/B4-1)) -> 95.625836 | D5: 131.07 | E5: =E4*(1+(D5/D4-1)) -> 99.824829 | F5: 52.42 | G5: =G4*(1+(F5/F4-1)) -> 76.57026
A6: 45755 | B6: 4982.77 | C6: =C5*(1+(B6/B5-1)) -> 84.906323 | D6: 116.42 | E6: =E5*(1+(D6/D5-1)) -> 88.667174 | F6: 45.2 | G6: =G5*(1+(F6/F5-1)) -> 66.023956
A7: 45777 | B7: 5569.06 | C7: =C6*(1+(B7/B6-1)) -> 94.896695 | D7: 131.32 | E7: =E6*(1+(D7/D6-1)) -> 100.01523 | F7: 54.91 | G7: =G6*(1+(F7/F6-1)) -> 80.20742
A8: 45807 | B8: 5912.17 | C8: =C7*(1+(B8/B7-1)) -> 100.74328 | D8: 142.82 | E8: =E7*(1+(D8/D7-1)) -> 108.7738 | F8: 65.8 | G8: =G7*(1+(F8/F7-1)) -> 96.114519
A9: 45838 | B9: 6204.95 | C9: =C8*(1+(B9/B8-1)) -> 105.73225 | D9: 147.52 | E9: =E8*(1+(D9/D8-1)) -> 112.35339 | F9: 73.25 | G9: =G8*(1+(F9/F8-1)) -> 106.99679
A10: 45869 | B10: 6339.39 | C10: =C9*(1+(B10/B9-1)) -> 108.02311 | D10: 152.01 | E10: =E9*(1+(D10/D9-1)) -> 115.77304 | F10: 78.42 | G10: =G9*(1+(F10/F9-1)) -> 114.54864
A11: 45898 | B11: 6460.26 | C11: =C10*(1+(B11/B10-1)) -> 110.08273 | D11: 152.01 | E11: =E10*(1+(D11/D10-1)) -> 115.77304 | F11: 90.39 | G11: =G10*(1+(F11/F10-1)) -> 132.0333
A12: 45930 | B12: 6688.46 | C12: =C11*(1+(B12/B11-1)) -> 113.97125 | D12: 154.23 | E12: =E11*(1+(D12/D11-1)) -> 117.46382 | F12: 98.64 | G12: =G11*(1+(F12/F11-1)) -> 144.08414
A13: 45961 | B13: 6840.2 | C13: =C12*(1+(B13/B12-1)) -> 116.5569 | D13: 155.06 | E13: =E12*(1+(D13/D12-1)) -> 118.09596 | F13: 114.35 | G13: =G12*(1+(F13/F12-1)) -> 167.03184
A14: 45979 | B14: 6617.32 | C14: =C13*(1+(B14/B13-1)) -> 112.75903 | D14: 149.85 | E14: =E13*(1+(D14/D13-1)) -> 114.12795 | F14: 104.31 | G14: =G13*(1+(F14/F13-1)) -> 152.36635
